Internal Server Error: /
Traceback (most recent call last):
  File "C:\Python310\lib\urllib\request.py", line 1348, in do_open
    h.request(req.get_method(), req.selector, req.data, headers,
  File "C:\Python310\lib\http\client.py", line 1282, in request
    self._send_request(method, url, body, headers, encode_chunked)
  File "C:\Python310\lib\http\client.py", line 1328, in _send_request
    self.endheaders(body, encode_chunked=encode_chunked)
  File "C:\Python310\lib\http\client.py", line 1277, in endheaders
    self._send_output(message_body, encode_chunked=encode_chunked)
  File "C:\Python310\lib\http\client.py", line 1037, in _send_output
    self.send(msg)
  File "C:\Python310\lib\http\client.py", line 975, in send
    self.connect()
  File "C:\Python310\lib\http\client.py", line 1447, in connect
    super().connect()
  File "C:\Python310\lib\http\client.py", line 941, in connect
    self.sock = self._create_connection(
  File "C:\Python310\lib\socket.py", line 824, in create_connection
    for res in getaddrinfo(host, port, 0, SOCK_STREAM):
  File "C:\Python310\lib\socket.py", line 955, in getaddrinfo
    for res in _socket.getaddrinfo(host, port, family, type, proto, flags):
socket.gaierror: [Errno 11001] getaddrinfo failed

During handling of the above exception, another exception occurred:

Traceback (most recent call last):
  File "D:\Documents\python\django_initial\employ_management_system\emp_rec-env\lib\site-packages\django\core\handlers\exception.py", line 55, in inner
    response = get_response(request)
  File "D:\Documents\python\django_initial\employ_management_system\emp_rec-env\lib\site-packages\django\core\handlers\base.py", line 197, in _get_response
    response = wrapped_callback(request, *callback_args, **callback_kwargs)
  File "D:\Documents\python\django_initial\api_log\app\views.py", line 9, in index
    source = urllib.request.urlopen('https://www.7timer.info/bin/astro.php?lon=113.2&lat=23.1&ac=0&unit=metric&output=json&tzshift=0').read()
  File "C:\Python310\lib\urllib\request.py", line 216, in urlopen
    return opener.open(url, data, timeout)
  File "C:\Python310\lib\urllib\request.py", line 519, in open
    response = self._open(req, data)
  File "C:\Python310\lib\urllib\request.py", line 536, in _open
    result = self._call_chain(self.handle_open, protocol, protocol +
  File "C:\Python310\lib\urllib\request.py", line 496, in _call_chain
    result = func(*args)
  File "C:\Python310\lib\urllib\request.py", line 1391, in https_open
    return self.do_open(http.client.HTTPSConnection, req,
  File "C:\Python310\lib\urllib\request.py", line 1351, in do_open
    raise URLError(err)
urllib.error.URLError: <urlopen error [Errno 11001] getaddrinfo failed>
Internal Server Error: /
Traceback (most recent call last):
  File "C:\Python310\lib\urllib\request.py", line 1348, in do_open
    h.request(req.get_method(), req.selector, req.data, headers,
  File "C:\Python310\lib\http\client.py", line 1282, in request
    self._send_request(method, url, body, headers, encode_chunked)
  File "C:\Python310\lib\http\client.py", line 1328, in _send_request
    self.endheaders(body, encode_chunked=encode_chunked)
  File "C:\Python310\lib\http\client.py", line 1277, in endheaders
    self._send_output(message_body, encode_chunked=encode_chunked)
  File "C:\Python310\lib\http\client.py", line 1037, in _send_output
    self.send(msg)
  File "C:\Python310\lib\http\client.py", line 975, in send
    self.connect()
  File "C:\Python310\lib\http\client.py", line 1447, in connect
    super().connect()
  File "C:\Python310\lib\http\client.py", line 941, in connect
    self.sock = self._create_connection(
  File "C:\Python310\lib\socket.py", line 824, in create_connection
    for res in getaddrinfo(host, port, 0, SOCK_STREAM):
  File "C:\Python310\lib\socket.py", line 955, in getaddrinfo
    for res in _socket.getaddrinfo(host, port, family, type, proto, flags):
socket.gaierror: [Errno 11001] getaddrinfo failed

During handling of the above exception, another exception occurred:

Traceback (most recent call last):
  File "D:\Documents\python\django_initial\employ_management_system\emp_rec-env\lib\site-packages\django\core\handlers\exception.py", line 55, in inner
    response = get_response(request)
  File "D:\Documents\python\django_initial\employ_management_system\emp_rec-env\lib\site-packages\django\core\handlers\base.py", line 197, in _get_response
    response = wrapped_callback(request, *callback_args, **callback_kwargs)
  File "D:\Documents\python\django_initial\api_log\app\views.py", line 9, in index
    source = urllib.request.urlopen('https://www.7timer.info/bin/astro.php?lon=113.2&lat=23.1&ac=0&unit=metric&output=json&tzshift=0').read()
  File "C:\Python310\lib\urllib\request.py", line 216, in urlopen
    return opener.open(url, data, timeout)
  File "C:\Python310\lib\urllib\request.py", line 519, in open
    response = self._open(req, data)
  File "C:\Python310\lib\urllib\request.py", line 536, in _open
    result = self._call_chain(self.handle_open, protocol, protocol +
  File "C:\Python310\lib\urllib\request.py", line 496, in _call_chain
    result = func(*args)
  File "C:\Python310\lib\urllib\request.py", line 1391, in https_open
    return self.do_open(http.client.HTTPSConnection, req,
  File "C:\Python310\lib\urllib\request.py", line 1351, in do_open
    raise URLError(err)
urllib.error.URLError: <urlopen error [Errno 11001] getaddrinfo failed>
"GET / HTTP/1.1" 500 136971
